Workbook

Sheet All Defects
A1: SCHEDULE-CONFLUENCE | B1: March by A14 | C1: March by A14 | D1: 1-April-18-April | E1: 21-April-13-May | F1: 2-June -6-June | G1: 9-June -25-June | H1: 26-June -2-July | I1: 3-July -23-July | J1: 24-July -30-July | K1: 31-July -21-Aug | L1: 15-Oct -19-Oct | M1: 22-Oct -7-Nov | N1: 9-Oct -7-Nov | O1: 4-Nov -10-Nov | P1: 11-Nov -21-Nov | Q1: 16-Dec -20-Dec | R1: 5-Jan -16-Jan | S1: 2-Feb -6-Feb | T1: 10-Feb To 23-Feb | U1: 18-Feb -26-Feb | V1: 23-Feb -6-Mar | W1: 5 VM | X1: 10-Mar-26(17th)-Mar | Y1: 19-Mar -2-April
A2: LRT OSV | B2: A13+A14 | C2: A12+A14 | D2: A13+A14 | E2: A12+A14 | F2: A12+A14 | G2: A13+A14 | H2: A12+A14 | I2: A13+A14 | J2: A12+A14 | K2: A13+A14 | L2: A12+A14 | M2: A13+A14 | N2: A14+A15 | O2: A12+A14 SU1-1 | P2: A13+A14 SU | Q2: A12+A14 SU1-2 | R2: A13+A14 SU1-2 | S2: A12+A14 SU2-1 | T2: A13+A14 SU2-1 | U2: A12+A14 SU2 | V2: A13+A14 SU2 | W2: A14+15 | X2: A14+15 | Y2: A13+A14 SU3 | Z2: A12+A14 SU3
A3: Cycle | B3: Sanity | C3: Sanity | D3: Full Cycle Sanity | E3: Full Cycle Sanity | F3: Cycle 1 | G3: Cycle 1 | H3: Cycle 2 | I3: Cycle 2 | J3: Cycle 3 | K3: Cycle 3 | L3: Cycle 4 | M3: Cycle 4 | N3: Pre LRT | O3: SU1-1 | P3: SU1-1 | Q3: SU1-2 | R3: SU1-2 | S3: SU2-1 | T3: SU2-1 | U3: SU2 | V3: SU2 | W3: LRT | X3: LRT | Y3: SU3 | Z3: SU3
A4: Iteration | B4: R4101 | C4: R7301 | D4: R4101 Dryrun | E4: R7401 | F4: R7402 | G4: R7411 | H4: R7403 | I4: R7412 | J4: R7404 | K4: R7413 | L4: R7405 | M4: R7414 | N4: R1591 | O4: R7406 | P4: R7415 | Q4: R7407 | R4: R7416 | S4: R7408 | T4: R7417 | U4: R7409 | V4: R7418 | W4: R1502 | X4: R1503 | Y4: R7419 | Z4: R7431
A5: Total TC Plan / Executed | B5: 490 | C5: 490 | D5: 12736 | E5: 12000 | F5: 4022 | G5: 14002 | H5: 4020 | I5: 14002 | J5: =SUM(J6:J7) -> 5616 | K5: =SUM(K6:K7) -> 14002 | L5: 6016 | M5: 14002 | N5: 12596 | O5: 6000 | P5: 14002 | Q5: 6000 | R5: 14002 | S5: 6000 | T5: =T6+T7 -> 8419 | U5: =U6+U7 -> 6434 | V5: =V6+V7 -> 14002 | W5: =W6+W7 -> 18528 | X5: =X6+X7 -> 17991 | Y5: =Y6+Y7 -> 14002 | Z5: =Z6+Z7 -> 6434
A6: Manual TC Executed | B6: 490 | C6: 490 | D6: 12736 | E6: 12000 | F6: 4022 | G6: 10790 | H6: 4020 | I6: 10502 | J6: 4016 | K6: 9478 | L6: 4016 | M6: 9002 | N6: 9608 | O6: 3000 | P6: 8209 | Q6: 2750 | R6: 7959 | S6: 2500 | T6: =7709-2290 -> 5419 | U6: =2500+492 -> 2992 | V6: 7709 | W6: 14500 | X6: 12000 | Y6: 7002 | Z6: 2434
A7: Automation TC Executed | B7: 0 | C7: 0 | D7: 0 | E7: 0 | F7: 0 | G7: 3212 | H7: 0 | I7: 3500 | J7: 1600 | K7: 4524 | L7: 2000 | M7: 5000 | N7: 2988 | O7: 3000 | P7: 5793 | Q7: 3250 | R7: 6043 | S7: 3500 | T7: =6293-3293 -> 3000 | U7: =3500-58 -> 3442 | V7: 6293 | W7: 4028 | X7: 5991 | Y7: 7000 | Z7: 4000
AD8: Total | AE8: Manual Defects | AF8: Automation defects
A9: Manual Defect Raised | B9: 0 | C9: 2 | D9: 72 | E9: 84 | F9: 8 | G9: 34 | H9: 24 | I9: 63 | J9: =28-1 -> 27 | K9: 78 | L9: 21 | M9: 68 | N9: 137 | O9: 8 | P9: 53 | Q9: 36 | R9: 75 | S9: 44 | T9: 51 | U9: 66 | V9: 53 | X9: 38 | AD9: 1002 | AE9: 966 | AF9: 37
A10: Automation Defect Raised | B10: 0 | C10: 0 | D10: 0 | E10: 0 | F10: 0 | G10: 2 | H10: 0 | I10: 2 | J10: 1 | K10: 5 | L10: 3 | M10: 1 | N10: 8 | O10: 1 | P10: 2 | Q10: 6 | R10: 2 | S10: 2 | T10: 1 | U10: 1 | V10: 2 | X10: 0
A11: Total Defect Raised | B11: =B9+B10 -> 0 | C11: =C9+C10 -> 2 | D11: =D9+D10 -> 72 | E11: =E9+E10 -> 84 | F11: =F9+F10 -> 8 | G11: =G9+G10 -> 36 | H11: =H9+H10 -> 24 | I11: =I9+I10 -> 65 | ... O11: =O9+O10 -> 9 | P11: =P9+P10-1 -> 54 | Q11: =Q9+Q10 -> 42 | R11: =R9+R10 -> 77 | S11: =S9+S10 -> 46 | T11: =T9+T10 -> 52 | U11: =U9+U10 -> 67 | V11: =V9+V10 -> 55 | X11: =X9+X10 -> 38 | Y11: =Y9+Y10 -> 0
A12: Manual Team defect density | B12: =B9/B6 -> 0 | C12: =C9/C6 -> 0.0040816327 | D12: =D9/D6 -> 0.0056532663 | E12: =E9/E6 -> 0.007 | F12: =F9/F6 -> 0.0019890602 | G12: =G9/G6 -> 0.0031510658 | H12: =H9/H6 -> 0.0059701493 | I12: =I9/I6 -> 0.0059988574 | ... V12: =V9/V6 -> 0.0068750811 | X12: =X9/X6 -> 0.0031666667 | Y12: =Y9/Y6 -> 0
A13: Automation Team defect density | B13: =B10/B7 -> #DIV/0! | C13: =C10/C7 -> #DIV/0! | D13: =D10/D7 -> #DIV/0! | E13: =E10/E7 -> #DIV/0! | F13: =F10/F7 -> #DIV/0! | G13: =G10/G7 -> 0.00062266501 | H13: =H10/H7 -> #DIV/0! | I13: =I10/I7 -> 0.00057142857 | ... V13: =V10/V7 -> 0.00031781344 | X13: =X10/X7 -> 0 | Y13: =Y10/Y7 -> 0
J14: AnkitLink | X14: Exe-link
A15: Project | B15: Iteration | D15: TC | E15: Total Defects | F15: S Rank | G15: A Rank | H15: B Rank | I15: C Rank | J15: linkALL | V15: MSR March | X15: MSR March
A16: LRT OSV | B16: OSV A13+A14 | C16: R4101 | D16: =B5 -> 490 | E16: =B11 -> 0 | F16: 0 | G16: 0 | H16: 0 | I16: 0 | J16: Checked ok
B17: OSV A12+A14 | C17: R7301 | D17: =C5 -> 490 | E17: =C11 -> 2 | F17: 1 | G17: 0 | H17: 1 | I17: 0 | J17: Sobia
B18: OSV A13+A14 | C18: R4101 | D18: =D5 -> 12736 | E18: =D11 -> 72 | F18: 11 | G18: 7 | H18: 32 | I18: 22 | J18: Checked ok | X18: 5811
B19: OSV A12+A14 | C19: R7401 | D19: =E5 -> 12000 | E19: =E11 -> 84 | F19: 6 | G19: 7 | H19: 34 | I19: 37 | J19: Checked ok | U19: 2500 | X19: 14002
B20: OSV A12+A14 | C20: R7402 Cycle 1 | D20: =F5 -> 4022 | E20: =F11 -> 8 | F20: 0 | G20: 0 | H20: 5 | I20: 3 | J20: Checked ok | U20: 2989
B21: OSV A13+A14 | C21: R7411 Cycle 1 | D21: 14002 | E21: =G11 -> 36 | F21: 0 | G21: =1+1 -> 2 | H21: =16+1 -> 17 | I21: 17 | J21: Checked ok | U21: =U20-U19 -> 489 | X21: 7709
B22: OSV A12+A14 | C22: R7403 Cycle 2 | D22: =H5 -> 4020 | E22: =H11 -> 24 | F22: 1 | G22: 1 | H22: 11 | I22: 11 | J22: Checked ok | X22: 3981
B23: OSV A13+A14 | C23: R7412 Cycle 2 | D23: =I5 -> 14002 | E23: =I11 -> 65 | F23: =2+3 -> 5 | G23: 6 | H23: 32 | I23: 22 | J23: Checked ok | U23: 2992 | Z23: =5811-3981 -> 1830
B24: OSV A12+A14 | C24: R7404 Cycle 3 | D24: =J5 -> 5616 | E24: =J11 -> 28 | F24: =1+1 -> 2 | G24: 2 | H24: 14 | I24: 10 | J24: Checked ok | U24: =U23-U19 -> 492 | X24: 6293
B25: OSV A13+A14 | C25: R7413 Cycle 3 | D25: =K5 -> 14002 | E25: =K11 -> 83 | F25: =2+1 -> 3 | G25: 18 | H25: =37+3 -> 40 | I25: =21+1 -> 22 | J25: Checked ok | X25: 1830
B26: OSV A12+A14 | C26: R7405 Cycle 4 | D26: =L5 -> 6016 | E26: =L11 -> 24 | F26: 0 | G26: =12+2 -> 14 | H26: 10 | I26: 0 | J26: Checked ok
B27: OSV A13+A14 | C27: R7414 Cycle 4 | D27: =M5 -> 14002 | E27: =M11 -> 69 | F27: =2+1 -> 3 | G27: 14 | H27: =38+1 -> 39 | I27: 13 | J27: Checked ok
B28: OSV A14+A15 | C28: R1591 | D28: =N5 -> 12596 | E28: =N11 -> 145 | F28: 5 | G28: =18+3 -> 21 | H28: =71+2 -> 73 | I28: =43+3 -> 46 | J28: Checked ok
B29: OSV A12+A14 SU1-1 | C29: R7406 SU1-1 | D29: =O5 -> 6000 | E29: =O11 -> 9 | F29: 0 | G29: 0 | H29: =5+1 -> 6 | I29: 3 | J29: Checked ok
B30: OSV A13+A14 SU1-1 | C30: R7415 SU1-1 | D30: =P5 -> 14002 | E30: =P11 -> 54 | F30: 0 | G30: 5 | H30: =32+2-1 -> 33 | I30: 16 | J30: Checked ok
B31: OSV A12+A14 SU1-2 | C31: R7407 SU1-2 | D31: =Q5 -> 6000 | E31: =Q11 -> 42 | F31: =0+1 -> 1 | G31: =3+1 -> 4 | H31: =23+4 -> 27 | I31: 10 | J31: Checked ok
B32: OSV A13+A14 SU1-2 | C32: R7416 SU1-2 | D32: =R5 -> 14002 | E32: =R11 -> 77 | F32: 1 | G32: 9 | H32: =45+2 -> 47 | I32: 20 | J32: Checked ok
B33: OSV A12+A14 SU2-1 | C33: R7408 SU2-1 | D33: =S5 -> 6000 | E33: =S11 -> 46 | F33: 1 | G33: 2 | H33: =29+2 -> 31 | I33: 12 | J33: Checked ok
B34: OSV A13+A14 SU2-1 [STOP/SKIP] | C34: R7417 SU2-1 | D34: =T5 -> 8419 | E34: =T11 -> 52 | F34: 0 | G34: 6 | H34: 25 | I34: =20+1 -> 21 | J34: Checked ok
B35: Additional LRT OSV A12+A14 SU2 | C35: R7409 SU2 | D35: =U5 -> 6434 | E35: =U11 -> 67 | F35: 1 | G35: 7 | H35: =40+1 -> 41 | I35: 18
B36: Additional LRT OSV A13+A14 SU2 | C36: R7418 SU2 | D36: =V5 -> 14002 | E36: =V11 -> 55 | F36: 1 | G36: =4+1 -> 5 | H36: =35+1 -> 36 | I36: 13
B37: OSV A14+A15 | C37: R1503 | D37: =X5 -> 17991 | E37: =X11 -> 38 | F37: 0 | G37: 6 | H37: 21 | I37: 11
B39: Total | D39: =SUM(D16:D30) -> 133996 | E39: =SUM(E16:E38) -> 1080 | F39: =SUM(F16:F37) -> 42 | G39: =SUM(G16:G37) -> 136 | H39: =SUM(H16:H36) -> 554 | I39: =SUM(I16:I37) -> 327
F41: Rankwise
A42: Data Asked by Vijay San on 18Sept
...

Sheet Defect Ranks
A1: LRT OSV | G1: Total defects Raised - Manual + Automation | Q1: Total defects - Manual (TC based) | V1: Total defects - Manual (Observations - not linked to TC) | AA1: Total (Manual + Automation) Defects - Status by 25 Sept 2025 12 PM
A2: Execution Iteration | C2: Test Cases Executed | F2: % | G2: Total defects –Automation (TC based) | L2: Total defects - Manual
A3: Iteration | B3: End date | C3: Total TC | D3: Manual | E3: Automation | F3: Manual | G3: Total | H3: S Rank | I3: A Rank | J3: B Rank | K3: C Rank | L3: Total | M3: S Rank | N3: A Rank | O3: B Rank | P3: C Rank | Q3: Total | R3: S Rank | S3: A Rank | T3: B Rank | U3: C Rank | V3: Total | W3: S Rank | X3: A Rank | Y3: B Rank | Z3: C Rank | AA3: Total | AB3: Draft | AC3: Waiting | AD3: In Investagtion | AE3: Block Fixing Validation | AF3: Closed Confirmation | AG3: Closed
A4: R4101 A13+A14 OSV | B4: 45734 | C4: 490 | D4: 490 | E4: 0 | F4: =D4/C4*100 -> 100 | G4: =SUM(H4:K4) -> 0 | H4: 0 | I4: 0 | J4: 0 | K4: 0 | L4: =SUM(M4:P4) -> 0 | M4: 0 | N4: 0 | O4: 0 | P4: 0 | Q4: =SUM(R4:U4) -> 0 | R4: 0 | S4: 0 | T4: 0 | U4: 0 | V4: =SUM(W4:Z4) -> 0 | W4: 0 | X4: 0 | Y4: 0 | Z4: 0 | AA4: =G4+L4 -> 0 | AB4: 0 | AC4: 0 | AD4: 0 | AE4: 0 | AF4: 0 | AG4: 0
A5: R7301 A12+A14 OSV | B5: 45742 | C5: 490 | D5: 490 | E5: 0 | F5: =D5/C5*100 -> 100 | G5: =SUM(H5:K5) -> 0 | H5: 0 | I5: 0 | J5: 0 | K5: 0 | L5: =SUM(M5:P5) -> 2 | M5: 1 | N5: 0 | O5: 1 | P5: 0 | Q5: =SUM(R5:U5) -> 0 | R5: 0 | S5: 0 | T5: 0 | U5: 0 | V5: =SUM(W5:Z5) -> 2 | W5: 1 | X5: 0 | Y5: 1 | Z5: 0 | AA5: =G5+L5 -> 2 | AB5: 0 | AC5: 0 | AD5: 0 | AE5: 0 | AF5: 0 | AG5: 2
A6: R4101 A13+A14 OSV | B6: 45765 | C6: 12736 | D6: 12736 | E6: 0 | F6: =D6/C6*100 -> 100 | G6: =SUM(H6:K6) -> 0 | H6: 0 | I6: 0 | J6: 0 | K6: 0 | L6: =SUM(M6:P6) -> 72 | M6: 11 | N6: 7 | O6: 32 | P6: 22 | Q6: =SUM(R6:U6) -> 22 | R6: 3 | S6: 2 | T6: 12 | U6: 5 | V6: =SUM(W6:Z6) -> 50 | W6: 8 | X6: 5 | Y6: 20 | Z6: 17 | AA6: =G6+L6 -> 72 | AB6: 0 | AC6: 0 | AD6: 7 | AE6: 7 | AF6: 9 | AG6: 49
A7: R7401 A12+A14 OSV | B7: 45790 | C7: 12000 | D7: 12000 | E7: 0 | F7: =D7/C7*100 -> 100 | G7: =SUM(H7:K7) -> 0 | H7: 0 | I7: 0 | J7: 0 | K7: 0 | L7: =SUM(M7:P7) -> 84 | M7: 6 | N7: 7 | O7: 34 | P7: 37 | Q7: =SUM(R7:U7) -> 20 | R7: 2 | S7: 1 | T7: 13 | U7: 4 | V7: =SUM(W7:Z7) -> 64 | W7: 4 | X7: 6 | Y7: 21 | Z7: 33 | AA7: =G7+L7 -> 84 | AB7: 0 | AC7: 0 | AD7: 4 | AE7: 14 | AF7: 12 | AG7: 54
A8: R7402 A12+A14 OSV | B8: 45814 | C8: 4022 | D8: 4022 | E8: 0 | F8: =D8/C8*100 -> 100 | G8: =SUM(H8:K8) -> 0 | H8: 0 | I8: 0 | J8: 0 | K8: 0 | L8: =SUM(M8:P8) -> 8 | M8: 0 | N8: 0 | O8: 5 | P8: 3 | Q8: =SUM(R8:U8) -> 5 | R8: 0 | S8: 0 | T8: 4 | U8: 1 | V8: =SUM(W8:Z8) -> 3 | W8: 0 | X8: 0 | Y8: 1 | Z8: 2 | AA8: =G8+L8 -> 8 | AB8: 0 | AC8: 0 | AD8: 0 | AE8: 1 | AF8: 1 | AG8: 6 | AK8: 211
A9: R7411 A13+A14 OSV | B9: 45833 | C9: 14002 | D9: 10790 | E9: 3212 | F9: =D9/C9*100 -> 77.06042 | G9: =SUM(H9:K9) -> 2 | H9: 0 | I9: 1 | J9: 1 | K9: 0 | L9: =SUM(M9:P9) -> 34 | M9: 0 | N9: 1 | O9: 16 | P9: 17 | Q9: =SUM(R9:U9) -> 4 | R9: 0 | S9: 0 | T9: 4 | U9: 0 | V9: =SUM(W9:Z9) -> 30 | W9: 0 | X9: 1 | Y9: 12 | Z9: 17 | AA9: =G9+L9 -> 36 | AB9: 0 | AC9: 0 | AD9: 2 | AE9: 6 | AF9: 4 | AG9: 24 | AK9: 367
A10: R7403 A12+A14 OSV | B10: 45840 | C10: 4020 | D10: 4020 | E10: 0 | F10: =D10/C10*100 -> 100 | G10: =SUM(H10:K10) -> 0 | H10: 0 | I10: 0 | J10: 0 | K10: 0 | L10: =SUM(M10:P10) -> 24 | M10: 1 | N10: 1 | O10: 11 | P10: 11 | Q10: =SUM(R10:U10) -> 1 | R10: 0 | S10: 1 | T10: 0 | U10: 0 | V10: =SUM(W10:Z10) -> 23 | W10: 1 | X10: 0 | Y10: 11 | Z10: 11 | AA10: =G10+L10 -> 24 | AB10: 0 | AC10: 0 | AD10: 1 | AE10: 9 | AF10: 1 | AG10: 13 | AK10: 137
A11: R7412 A13+ A14 OSV | B11: 45863 | C11: 14002 | D11: 10502 | E11: 3500 | F11: =D11/C11*100 -> 75.003571 | G11: =SUM(H11:K11) -> 2 | H11: 2 | I11: 0 | J11: 0 | K11: 0 | L11: =SUM(M11:P11) -> 63 | M11: 3 | N11: 6 | O11: 32 | P11: 22 | Q11: =SUM(R11:U11) -> 3 | R11: 0 | S11: 2 | T11: 1 | U11: 0 | V11: =SUM(W11:Z11) -> 60 | W11: 3 | X11: 4 | Y11: 31 | Z11: 22 | AA11: =G11+L11 -> 65 | AB11: 0 | AC11: 3 | AD11: 9 | AE11: 20 | AF11: 6 | AG11: 27
A12: R7404 A12+ A14 OSV | B12: 45868 | C12: 5616 | D12: 4016 | E12: 1600 | F12: =D12/C12*100 -> 71.509972 | G12: =SUM(H12:K12) -> 1 | H12: 1 | I12: 0 | J12: 0 | K12: 0 | L12: =SUM(M12:P12) -> 27 | M12: 1 | N12: 2 | O12: 14 | P12: 10 | Q12: =SUM(R12:U12) -> 1 | R12: 0 | S12: 0 | T12: 1 | U12: 0 | V12: =SUM(W12:Z12) -> 26 | W12: 1 | X12: 2 | Y12: 13 | Z12: 10 | AA12: =G12+L12 -> 28 | AB12: 0 | AC12: 6 | AD12: 3 | AE12: 7 | AF12: 5 | AG12: 7
A13: R7413 A13+ A14 OSV | B13: 45890 | C13: 14002 | D13: 9478 | E13: 4524 | F13: =D13/C13*100 -> 67.69033 | G13: =SUM(H13:K13) -> 5 | H13: 1 | I13: 0 | J13: 3 | K13: 1 | L13: =SUM(M13:P13) -> 78 | M13: 2 | N13: 18 | O13: 37 | P13: 21 | Q13: =SUM(R13:U13) -> 4 | R13: 0 | S13: 2 | T13: 2 | U13: 0 | V13: =SUM(W13:Z13) -> 74 | W13: 2 | X13: 16 | Y13: 35 | Z13: 21 | AA13: =G13+L13 -> 83 | AB13: 0 | AC13: 38 | AD13: 7 | AE13: 9 | AF13: 11 | AG13: 18
A14: R7405 A12+ A14 OSV | B14: 45919 | C14: 6016 | D14: 4016 | E14: 2000 | F14: =D14/C14*100 -> 66.755319 | G14: =SUM(H14:K14) -> 3 | H14: 0 | I14: 2 | J14: 1 | K14: 0 | L14: =SUM(M14:P14) -> 21 | M14: 0 | N14: 0 | O14: 13 | P14: 8 | Q14: =SUM(R14:U14) -> 3 | R14: 0 | S14: 0 | T14: 2 | U14: 1 | V14: =SUM(W14:Z14) -> 18 | W14: 0 | X14: 0 | Y14: 11 | Z14: 7 | AA14: =G14+L14 -> 24 | AB14: 0 | AC14: 22 | AD14: 1 | AE14: 0 | AF14: 1 | AG14: 0
A15: R7414 A13+ A14 OSV | B15: 45937 | C15: 14002 | D15: 9002 | E15: 5000 | F15: =D15/C15*100 -> 64.290816 | G15: =SUM(H15:K15) -> 1 | H15: 1 | I15: 0 | J15: 0 | K15: 0 | L15: =SUM(M15:P15) -> 68 | M15: 2 | N15: 16 | O15: 38 | P15: 12 | Q15: =SUM(R15:U15) -> 6 | R15: 0 | S15: 1 | T15: 5 | U15: 0 | V15: =SUM(W15:Z15) -> 62 | W15: 2 | X15: 15 | Y15: 33 | Z15: 12 | AA15: =G15+L15 -> 69 | AB15: 0 | AC15: 47 | AD15: 2 | AE15: 11 | AF15: 5 | AG15: 4
A16: R1591 A14+ A15 OSV | B16: 45968 | C16: ='All Defects'!N5 -> 12596 | D16: ='All Defects'!N6 -> 9608 | E16: ='All Defects'!N7 -> 2988 | F16: =D16/C16*100 -> 76.278184 | G16: =SUM(H16:K16) -> 8 | H16: 0 | I16: 3 | J16: 2 | K16: 3 | L16: =SUM(M16:P16) -> 137 | M16: 5 | N16: 18 | O16: 71 | P16: 43 | Q16: =SUM(R16:U16) -> 15 | R16: 1 | S16: 4 | T16: 7 | U16: 3 | V16: =SUM(W16:Z16) -> 122 | W16: 4 | X16: 14 | Y16: 64 | Z16: 40 | AA16: =G16+L16 -> 145
A17: R7406 A12+ A14 OSV | B17: 45972 | C17: 6000 | D17: 3000 | E17: 3000 | F17: =D17/C17*100 -> 50 | G17: =SUM(H17:K17) -> 1 | H17: 0 | I17: 0 | J17: 1 | K17: 0 | L17: =SUM(M17:P17) -> 8 | M17: 0 | N17: 0 | O17: 5 | P17: 3 | Q17: =SUM(R17:U17) -> 0 | R17: 0 | S17: 0 | T17: 0 | U17: 0 | V17: =SUM(W17:Z17) -> 8 | W17: 0 | X17: 0 | Y17: 5 | Z17: 3 | AA17: =G17+L17 -> 9
A18: R7415 A13+ A14 OSV | B18: 45982 | C18: 14002 | D18: 8209 | E18: 5793 | F18: =D18/C18*100 -> 58.627339 | G18: =SUM(H18:K18) -> 2 | H18: 0 | I18: 0 | J18: 2 | K18: 0 | L18: =SUM(M18:P18) -> 53 | M18: 0 | N18: 5 | O18: 32 | P18: 16 | Q18: =SUM(R18:U18) -> 3 | R18: 0 | S18: 1 | T18: 2 | U18: 0 | V18: =SUM(W18:Z18) -> 50 | W18: 0 | X18: 4 | Y18: 30 | Z18: 16 | AA18: =G18+L18 -> 55
A19: R7407 A12+ A14 OSV | B19: 46011 | C19: 6000 | D19: 2750 | E19: 3250 | F19: =D19/C19*100 -> 45.833333 | G19: =SUM(H19:K19) -> 3 | H19: 1 | I19: 0 | J19: 2 | K19: 0 | L19: =SUM(M19:P19) -> 36 | M19: 0 | N19: 3 | O19: 23 | P19: 10 | Q19: =SUM(R19:U19) -> 2 | R19: 0 | S19: 0 | T19: 1 | U19: 1 | V19: =SUM(W19:Z19) -> 33 | W19: 0 | X19: 2 | Y19: 22 | Z19: 9
A20: R7416 A13+ A14 OSV | B20: 46039 | C20: ='All Defects'!R5 -> 14002 | D20: ='All Defects'!R7 -> 6043 | E20: ='All Defects'!R6 -> 7959 | F20: =D20/C20*100 -> 43.15812 | G20: =SUM(H20:K20) -> 2 | H20: 0 | I20: 0 | J20: 2 | K20: 0 | L20: =SUM(M20:P20) -> 75 | M20: 1 | N20: 9 | O20: 45 | P20: 20 | Q20: =SUM(R20:U20) -> 1 | R20: 0 | S20: 0 | T20: 1 | U20: 0 | V20: =SUM(W20:Z20) -> 74 | W20: 1 | X20: 9 | Y20: 44 | Z20: 20
A21: R7408 A12+ A14 OSV | B21: 46059 | C21: ='All Defects'!S5 -> 6000 | D21: ='All Defects'!S7 -> 3500 | E21: ='All Defects'!S6 -> 2500 | F21: =D21/C21*100 -> 58.333333 | G21: =SUM(H21:K21) -> 2 | H21: 0 | I21: 0 | J21: 2 | K21: 0 | L21: =SUM(M21:P21) -> 44 | M21: 1 | N21: 2 | O21: 29 | P21: 12 | Q21: =SUM(R21:U21) -> 0 | R21: 0 | S21: 0 | T21: 0 | U21: 0 | V21: =SUM(W21:Z21) -> 44 | W21: 1 | X21: 2 | Y21: 29 | Z21: 12
A22: R7417 A13+ A14 OSV | B22: 46076 | C22: ='All Defects'!T5 -> 8419 | D22: ='All Defects'!T7 -> 3000 | E22: ='All Defects'!T6 -> 5419 | F22: =D22/C22*100 -> 35.633686 | G22: =SUM(H22:K22) -> 1 | H22: 0 | I22: 0 | J22: 0 | K22: 1 | L22: =SUM(M22:P22) -> 51 | M22: 0 | N22: 6 | O22: 25 | P22: 20 | Q22: =SUM(R22:U22) -> 0 | R22: 0 | S22: 0 | T22: 0 | U22: 0 | V22: =SUM(W22:Z22) -> 51 | W22: 0 | X22: 6 | Y22: 25 | Z22: 20
A23: R7409 Additional LRT OSV A12+A14 SU2 | B23: 46078 | C23: ='All Defects'!U5 -> 6434 | D23: ='All Defects'!U7 -> 3442 | E23: ='All Defects'!U6 -> 2992 | F23: =D23/C23*100 -> 53.497047 | G23: =SUM(H23:K23) -> 1 | H23: 0 | I23: 0 | J23: 1 | K23: 0 | L23: =SUM(M23:P23) -> 66 | M23: 1 | N23: 7 | O23: 40 | P23: 18 | Q23: =SUM(R23:U23) -> 3 | R23: 1 | S23: 0 | T23: 2 | U23: 0 | V23: =SUM(W23:Z23) -> 63 | W23: 0 | X23: 7 | Y23: 38 | Z23: 18
A24: R7418 Additional LRT OSV A13+A14 SU2 | B24: 46087 | C24: ='All Defects'!V5 -> 14002 | D24: ='All Defects'!V7 -> 6293 | E24: ='All Defects'!V6 -> 7709 | F24: =D24/C24*100 -> 44.943579 | G24: =SUM(H24:K24) -> 2 | H24: 0 | I24: 1 | J24: 1 | K24: 0 | L24: 53 | M24: 1 | N24: 4 | O24: 35 | P24: 13 | Q24: =SUM(R24:U24) -> 1 | R24: 0 | S24: 0 | T24: 1 | U24: 0 | V24: =SUM(W24:Z24) -> 52 | W24: 1 | X24: 4 | Y24: 34 | Z24: 13
A25: R1503 A14+ A15 OSV | B25: 46098 | C25: ='All Defects'!X5 -> 17991 | D25: ='All Defects'!X7 -> 5991 | E25: ='All Defects'!X6 -> 12000 | F25: =D25/C25*100 -> 33.299983 | G25: =SUM(H25:K25) -> 0 | H25: 0 | I25: 0 | J25: 0 | K25: 0 | L25: =SUM(M25:P25) -> 38 | M25: 0 | N25: 6 | O25: 21 | P25: 11 | Q25: =SUM(R25:U25) -> 2 | R25: 0 | S25: 0 | T25: 2 | U25: 0 | V25: =SUM(W25:Z25) -> 36 | W25: 0 | X25: 6 | Y25: 19 | Z25: 11
A26: R7419 A13+ A14 OSV
A27: Sum | G27: =SUM(G4:G23) -> 34 | H27: =SUM(H4:H25) -> 6 | I27: =SUM(I4:I25) -> 7 | J27: =SUM(J4:J25) -> 18 | K27: =SUM(K4:K25) -> 5 | L27: =SUM(L4:L23) -> 951 | M27: =SUM(M4:M25) -> 36 | N27: =SUM(N4:N25) -> 118 | O27: =SUM(O4:O25) -> 559 | P27: =SUM(P4:P25) -> 329 | Q27: =SUM(Q4:Q23) -> 93 | R27: =SUM(R4:R25) -> 7 | S27: =SUM(S4:S25) -> 14 | T27: =SUM(T4:T25) -> 60 | U27: =SUM(U4:U25) -> 15 | V27: =SUM(V4:V23) -> 857 | W27: =SUM(W4:W25) -> 29 | X27: =SUM(X4:X25) -> 103 | Y27: =SUM(Y4:Y25) -> 499 | Z27: =SUM(Z4:Z25) -> 314 | AA27: =SUM(AA4:AA15) -> 495 | AB27: =SUM(AB4:AB17) -> 0 | AC27: =SUM(AC4:AC17) -> 116 | AD27: =SUM(AD4:AD17) -> 36 | AE27: =SUM(AE4:AE17) -> 84 | AF27: =SUM(AF4:AF17) -> 55 | AG27: =SUM(AG4:AG17) -> 204
G28: 15 | AA28: Percentage | AB28: =AB27/V27*100 -> 0 | AC28: =AC27/AA27*100 -> 23.434343 | AD28: =AD27/AA27*100 -> 7.2727273 | AE28: =AE27/AA27*100 -> 16.969697 | AF28: =AF27/AA27*100 -> 11.111111 | AG28: =AG27/AA27*100 -> 41.212121
B29: 1 | C29: Sowfware quality of OSV & NL build are there any difference?
C30: No - theny why is defect is not found in NL: Most of defct is outside TC detection.
C31: Yes:-
B32: 2 | C32: 1. During test case execution , after completing one test case TE moves to another test case execution while doing precondition of another test case TE observe defect in between this transition hence TE report to TL and after conclusion TE report the defect .KPIT Team has taken alignment for this with Tamanaha and Yamaguch San 2. TLs and TE regular discussion on scenario and defects & we try fixed defect scenario during test case execution so that we can get defects there and also , not all are replica of OSV , few OSV are replica of NL 3. Test Case based defect leakage is not there in A14 NL and OSV

Sheet Sheet1
A1: Iteration | B1: Manual Defect Dashboard Link | C1: Total Defects | D1: Out of TC Defects | E1: TC Defects | F1: Iteration
A2: R7406 A12+ A14 OSV - SU1-1 | B2: https://jira.honda-ivi.com/secure/Dashboard.jspa?selectPageId=22124 | C2: 8 | D2: 8 | E2: 0 | F2: Completed
A3: R7415 A12+ A14 OSV - SU1-1 | B3: https://jira.honda-ivi.com/secure/Dashboard.jspa?selectPageId=22146 | C3: 53 | D3: 50 | E3: 3 | F3: Completed
A4: R7407 A12+ A14 OSV -SU1-2 | B4: https://jira.honda-ivi.com/secure/Dashboard.jspa?selectPageId=22676 | C4: 8 | D4: 7 | E4: 1 | F4: In progress

Sheet TE Def Trend
A1: Tester | B1: R4101 | C1: R7401 | D1: R7402 | E1: R7411 | F1: R7403 | G1: R7412 | H1: R7404 | I1: R7413 | J1: R7405 | K1: R7414 | L1: R1591 | M1: R7406 | N1: R7415 | O1: R7407 | P1: R7416 | Q1: R7408 | R1: R7417 | S1: R7409 | T1: R7418 | U1: OSV Total | V1: A14 NL | W1: Tester | X1: Total | Y1: Replica | Z1: Unique Defects | AT1: Tester | AU1: OSV Total
A2: KPT Md Lucky | B2: 11 | C2: 12 | D2: 0 | E2: 3 | F2: 2 | G2: 2 | H2: 4 | I2: 5 | J2: 2 | K2: 4 | L2: 7 | M2: 0 | N2: 2 | O2: 7 | P2: 6 | Q2: 3 | R2: 5 | S2: 3 | T2: 2 | U2: =SUM(B2:T2) -> 80 | V2: 11 | W2: KPT Md Lucky | X2: =U2 -> 80 | AT2: KPT Md Lucky | AU2: 61
A3: KPT Ayush Mishra | B3: 3 | C3: 6 | D3: 0 | E3: 3 | F3: 1 | G3: 3 | H3: 1 | I3: 8 | J3: 1 | K3: 4 | L3: 7 | M3: 0 | N3: 3 | O3: 2 | P3: 5 | Q3: 2 | R3: 2 | S3: 6 | T3: 3 | U3: =SUM(B3:T3) -> 60 | V3: 18 | W3: KPT Ayush Mishra | X3: =U3 -> 60 | AT3: KPT Mansi Tehra | AU3: 43
A4: KPT Ashwini Karale | B4: 4 | C4: 4 | D4: 1 | E4: 2 | F4: 2 | G4: 3 | H4: 3 | I4: 9 | J4: 0 | K4: 3 | L4: 9 | M4: 2 | N4: 2 | O4: 0 | U4: =SUM(B4:O4) -> 44 | V4: 10 | W4: KPT Ashwini Karale | X4: =U4 -> 44 | AT4: KPT Ayush Mishra | AU4: 42
A5: KPT Arpitha | B5: - | C5: - | D5: 1 | E5: 2 | F5: 3 | G5: 5 | H5: - | I5: - | J5: - | K5: 5 | L5: 21 | M5: - | N5: 11 | O5: 1 | P5: 8 | Q5: 7 | R5: 4 | S5: 8 | T5: 8 | U5: =SUM(B5:T5) -> 84 | W5: KPT Arpitha | X5: =U5 -> 84 | AT5: KPT Prashant Gaikwad | AU5: 39
A6: KPT Mansi Tehra | B6: 8 | C6: 14 | D6: 0 | E6: 1 | F6: 2 | G6: 4 | H6: 0 | I6: 4 | J6: 0 | K6: 6 | L6: 4 | M6: 0 | N6: 0 | O6: 0 | P6: 2 | Q6: 1 | R6: 1 | S6: 5 | T6: 2 | U6: =SUM(B6:T6) -> 54 | V6: 5 | W6: KPT Mansi Tehra | X6: =U6 -> 54 | AT6: KPT Aniket Chaudhari | AU6: 29
A7: KPT Prashant Gaikwad | B7: 5 | C7: 4 | D7: 1 | E7: 1 | F7: 1 | G7: 2 | H7: 0 | I7: 6 | J7: 2 | K7: 4 | L7: 6 | M7: 0 | N7: 3 | O7: 4 | P7: 5 | Q7: 1 | R7: 2 | S7: 5 | T7: 1 | U7: =SUM(B7:T7) -> 53 | V7: 8 | W7: KPT Prashant Gaikwad | X7: =U7 -> 53 | AT7: KPT Shivanand Miraje | AU7: 28
A8: KPT Yogeshwari Saratkar | B8: 3 | C8: 6 | D8: 1 | E8: 3 | F8: 4 | G8: 5 | H8: 1 | I8: 2 | J8: 2 | K8: 3 | L8: 4 | M8: 0 | N8: 6 | O8: 0 | U8: =SUM(B8:O8) -> 40 | V8: 2 | W8: KPT Yogeshwari Saratkar | X8: =U8 -> 40 | AT8: KPT Prachi Gahile | AU8: 27
A9: KPT Pravin Khade | B9: 3 | C9: 9 | D9: 0 | E9: 4 | F9: 2 | G9: 4 | H9: 2 | I9: 6 | J9: 3 | K9: 4 | L9: - | M9: - | N9: - | O9: - | P9: - | Q9: - | R9: - | S9: - | T9: - | U9: =SUM(B9:N9) -> 37 | V9: 4 | W9: KPT Pravin Khade | X9: =U9 -> 37 | AT9: KPT Shalaka Walke | AU9: 25
A10: KPT Prachi Gahile | B10: 2 | C10: 3 | D10: 0 | E10: 1 | F10: 0 | G10: 2 | H10: 2 | I10: 4 | J10: 2 | K10: 3 | L10: 8 | M10: 0 | N10: 0 | O10: 0 | P10: 1 | Q10: 1 | R10: 3 | S10: 6 | T10: 4 | U10: =SUM(B10:T10) -> 42 | V10: 14 | W10: KPT Prachi Gahile | X10: =U10 -> 42 | AT10: KPT Jitendra Gunjal | AU10: 21
A11: KPT Dinesh Patil | B11: - | C11: - | D11: - | E11: - | G11: 3 | H11: - | I11: 1 | J11: 1 | K11: 4 | L11: 13 | M11: 1 | N11: 7 | O11: 3 | P11: 7 | Q11: 8 | R11: 8 | S11: 5 | T11: 9 | U11: =SUM(B11:T11) -> 70 | V11: 4 | W11: KPT Dinesh Patil | X11: =U11 -> 70 | AT11: KPT Apoorva Thomre | AU11: 18
A12: Shekhar Rane | B12: - | C12: - | D12: - | E12: - | F12: - | G12: - | H12: - | I12: 5 | J12: - | K12: - | L12: 3 | M12: - | N12: - | O12: - | P12: 4 | U12: =SUM(B12:N12) -> 8 | V12: 26 | W12: Shekhar Rane | X12: =U12 -> 8 | AT12: KPT Praveen Reddimalla | AU12: 16
A13: KPT Shivanand Miraje | B13: 3 | C13: 2 | D13: 0 | E13: 3 | F13: 1 | G13: 3 | H13: 1 | I13: 4 | J13: 0 | K13: 5 | L13: 5 | M13: 0 | O13: 1 | P13: 2 | U13: =SUM(B13:P13) -> 30 | V13: 5 | W13: KPT Shivanand Miraje | X13: =U13 -> 30 | AT13: KPT Karthik Reddy | AU13: 12
A14: KPT Aniket Chaudhari | B14: - | C14: 1 | D14: 0 | E14: 0 | F14: 1 | G14: 3 | H14: 1 | I14: 1 | J14: 1 | K14: 4 | L14: 6 | M14: 0 | N14: 3 | O14: 8 | P14: 6 | Q14: 2 | R14: 3 | S14: 5 | T14: 4 | U14: =SUM(B14:T14) -> 49 | V14: 9 | W14: KPT Aniket Chaudhari | X14: =U14 -> 49 | AT14: KPT Arpit Nayak | AU14: 11
A15: KPT Shalaka Walke | B15: 1 | C15: 4 | D15: 1 | E15: 1 | F15: 1 | G15: 6 | H15: 2 | I15: 1 | J15: - | K15: 3 | L15: 4 | M15: - | N15: - | O15: 1 | P15: 3 | Q15: 0 | R15: 2 | S15: 3 | T15: 0 | U15: =SUM(B15:P15) -> 28 | V15: 4 | W15: KPT Shalaka Walke | X15: =U15 -> 28 | AT15: KPT Piyush Kumar | AU15: 11
A16: KPT Apoorva Thomre | B16: - | C16: - | D16: - | E16: 1 | F16: 1 | G16: 3 | H16: 0 | I16: 3 | J16: 1 | K16: 5 | L16: 2 | M16: 0 | N16: 2 | O16: 0 | P16: 1 | Q16: 1 | R16: 1 | S16: 3 | T16: 0 | U16: =SUM(B16:T16) -> 24 | V16: 7 | W16: KPT Apoorva Thomre | X16: =U16 -> 24 | AT16: Shekhar Rane | AU16: 8
A17: KPT Jitendra Gunjal | B17: 5 | C17: 2 | D17: 0 | E17: 0 | F17: 0 | G17: 2 | H17: 2 | I17: 1 | J17: 0 | K17: 1 | L17: 4 | M17: 0 | N17: 2 | O17: 2 | P17: 1 | R17: 2 | S17: 4 | T17: 1 | U17: =SUM(B17:P17) -> 22 | V17: 4 | W17: KPT Jitendra Gunjal | X17: =U17 -> 22 | AT17: Amrit Raj | AU17: 6
A18: KPT Arpit Nayak | B18: - | C18: - | D18: - | E18: - | F18: - | G18: - | H18: - | I18: 1 | J18: 1 | K18: 2 | L18: 4 | M18: 3 | P18: 3 | T18: 1 | U18: =SUM(B18:N18) -> 11 | V18: 11 | W18: KPT Arpit Nayak | X18: =U18 -> 11 | AT18: Gorakhnath | AU18: 2
A19: KPT Karan Mashal | B19: 0 | C19: 4 | D19: 0 | E19: 2 | F19: 1 | G19: 4 | H19: 3 | I19: 2 | J19: 1 | K19: 3 | L19: - | M19: - | N19: - | O19: - | U19: =SUM(B19:N19) -> 20 | W19: KPT Karan Mashal | X19: =U19 -> 20
A20: KPT Praveen Reddimalla | B20: 1 | C20: 1 | D20: 0 | E20: 3 | F20: 1 | G20: 1 | H20: 1 | I20: 4 | J20: 0 | K20: 1 | L20: 2 | M20: 0 | O20: 1 | P20: 2 | S20: 3 | T20: 2 | U20: =SUM(B20:P20) -> 18 | V20: 5 | W20: KPT Praveen Reddimalla | X20: =U20 -> 18
A21: KPT Piyush Kumar | B21: 2 | C21: - | D21: 2 | E21: - | F21: - | G21: - | H21: - | I21: 1 | J21: 2 | K21: 0 | L21: 3 | M21: 1 | P21: 1 | Q21: 1 | U21: =SUM(B21:N21) -> 11 | V21: 9 | W21: KPT Piyush Kumar | X21: =U21 -> 11
A22: Adarsh kp | B22: - | C22: - | D22: - | E22: - | F22: - | G22: 2 | H22: - | I22: - | J22: - | K22: - | L22: 10 | M22: 1 | N22: 6 | O22: 4 | P22: 8 | Q22: 12 | R22: 8 | S22: 4 | T22: 9 | U22: =SUM(B22:T22) -> 64 | W22: Adarsh kp | X22: =U22 -> 64
A23: KPT Bharati Jagtap | B23: 4 | C23: 3 | D23: 0 | E23: 1 | F23: 1 | G23: 2 | H23: 1 | I23: 2 | J23: - | K23: - | L23: - | M23: - | U23: =SUM(B23:N23) -> 14 | W23: KPT Bharati Jagtap | X23: =U23 -> 14
A24: KPT Karthik Reddy | B24: - | C24: - | D24: - | E24: - | F24: - | G24: 1 | H24: - | I24: 2 | J24: 2 | K24: 2 | L24: 3 | M24: 0 | N24: - | O24: 2 | P24: 3 | R24: 3 | U24: =SUM(B24:P24) -> 15 | V24: 12 | W24: KPT Karthik Reddy | X24: =U24 -> 15
A25: KPT Lakshmana Sampathirao | B25: - | C25: - | D25: - | E25: - | F25: - | G25: 0 | H25: 1 | I25: 1 | J25: 0 | K25: 2 | L25: 2 | M25: 0 | N25: - | O25: - | P25: - | Q25: - | R25: - | S25: - | T25: - | U25: =SUM(B25:N25) -> 6 | V25: 4 | W25: KPT Lakshmana Sampathirao | X25: =U25 -> 6
A26: KPT Abhinandan Bankar | B26: 1 | C26: 2 | D26: 0 | E26: 0 | F26: 0 | G26: 1 | H26: 1 | I26: 4 | J26: - | K26: - | L26: - | M26: - | N26: - | O26: - | P26: - | Q26: - | R26: - | S26: - | T26: - | U26: =SUM(B26:N26) -> 9 | W26: KPT Abhinandan Bankar | X26: =U26 -> 9
A27: Amrit Raj | B27: - | C27: - | D27: - | E27: - | F27: - | G27: - | H27: - | I27: - | J27: - | K27: - | L27: 2 | M27: - | N27: 4 | O27: 0 | P27: 3 | Q27: 3 | R27: 3 | S27: 4 | T27: 3 | U27: =SUM(B27:N27) -> 6 | V27: 3 | W27: Amrit Raj | X27: =U27 -> 6
A28: Rajat singh | B28: - | C28: - | D28: - | E28: - | F28: - | G28: - | H28: - | I28: - | J28: - | K28: - | L28: 7 | M28: - | N28: - | O28: - | P28: - | Q28: - | R28: - | S28: - | T28: - | U28: =SUM(B28:N28) -> 7 | W28: Rajat singh | X28: =U28 -> 7
A29: Gorakhnath | B29: - | C29: - | D29: - | E29: - | F29: - | G29: - | H29: - | I29: - | J29: - | K29: - | L29: - | M29: - | N29: 2 | P29: 4 | Q29: 2 | R29: 4 | S29: 2 | T29: 2 | U29: =SUM(B29:N29) -> 2 | V29: 5 | W29: Gorakhnath | X29: =U29 -> 2
A30: KPT Shailesh D | B30: 3 | C30: - | D30: - | E30: - | F30: - | G30: 2 | H30: - | I30: - | J30: - | K30: - | L30: - | M30: - | N30: - | O30: - | P30: - | Q30: - | R30: - | S30: - | T30: - | U30: =SUM(B30:N30) -> 5 | W30: KPT Shailesh D | X30: =U30 -> 5
A31: KPT Sohan Ubale | B31: 0 | C31: 3 | D31: 1 | E31: 0 | F31: - | G31: - | H31: - | I31: - | J31: - | K31: - | L31: - | M31: - | N31: - | U31: =SUM(B31:N31) -> 4 | W31: KPT Sohan Ubale | X31: =U31 -> 4
A32: Kumar Abhijeet | B32: 3 | C32: 1 | D32: - | E32: - | F32: - | G32: - | H32: - | I32: - | J32: - | K32: - | L32: - | M32: - | N32: - | O32: - | P32: - | Q32: - | R32: - | S32: - | T32: - | U32: =SUM(B32:N32) -> 4 | W32: Kumar Abhijeet | X32: =U32 -> 4
A33: Shweta Agrawal | B33: 4 | C33: - | D33: - | E33: - | F33: - | G33: - | H33: - | I33: - | J33: - | K33: - | L33: - | M33: - | N33: - | O33: - | P33: - | Q33: - | R33: - | S33: - | T33: - | U33: =SUM(B33:N33) -> 4 | W33: Shweta Agrawal | X33: =U33 -> 4
A34: KPT Karuvedi Naveen Kumar | B34: - | C34: - | D34: - | E34: - | F34: - | G34: 0 | H34: 2 | I34: 1 | J34: - | K34: - | L34: - | M34: - | N34: - | U34: =SUM(B34:N34) -> 3 | W34: KPT Karuvedi Naveen Kumar | X34: =U34 -> 3
A35: Vishal Shelke | B35: 3 | C35: - | D35: - | E35: - | F35: - | G35: - | H35: - | I35: - | J35: - | K35: - | L35: - | M35: - | N35: - | O35: - | P35: - | Q35: - | R35: - | S35: - | T35: - | U35: =SUM(B35:N35) -> 3 | W35: Vishal Shelke | X35: =U35 -> 3
A36: Gaurav Gupta | C36: 2 | D36: - | E36: - | F36: - | G36: - | H36: - | I36: - | J36: - | K36: - | L36: - | M36: - | N36: - | O36: - | P36: - | Q36: - | R36: - | S36: - | T36: - | U36: =SUM(B36:N36) -> 2 | W36: Gaurav Gupta | X36: =U36 -> 2
A37: Vaibhav Malte | B37: 1 | C37: 1 | D37: - | E37: - | F37: - | G37: - | H37: - | I37: - | J37: - | K37: - | L37: - | M37: - | N37: - | O37: - | P37: - | Q37: - | R37: - | S37: - | T37: - | U37: =SUM(B37:N37) -> 2 | W37: Vaibhav Malte | X37: =U37 -> 2
A38: KPT Prasad Aute | B38: - | C38: - | D38: - | E38: 1 | F38: 0 | G38: 0 | H38: 0 | I38: 0 | J38: - | K38: - | L38: - | M38: - | N38: - | O38: - | P38: - | Q38: - | R38: - | S38: - | T38: - | U38: =SUM(B38:N38) -> 1 | W38: KPT Prasad Aute | X38: =U38 -> 1
A39: Rajat singh | B39: 1 | C39: - | D39: - | E39: - | F39: - | G39: - | H39: - | I39: - | J39: - | K39: - | L39: - | M39: - | N39: - | O39: - | P39: - | Q39: - | R39: - | S39: - | T39: - | U39: =SUM(B39:N39) -> 1 | W39: Rajat singh | X39: =U39 -> 1
A40: Ashish Kadam | B40: 1 | C40: - | D40: - | E40: - | F40: - | G40: - | H40: - | I40: - | J40: - | K40: - | L40: - | M40: - | N40: - | O40: - | P40: - | Q40: - | R40: - | S40: - | T40: - | U40: =SUM(B40:N40) -> 1 | W40: Ashish Kadam | X40: =U40 -> 1
...

Sheet Density
A1: Iteration | B1: Manual TC Executed | C1: TC Effectiveness | D1: Manual DD | E1: Automation TC Executed | F1: Automation Defects Raised | G1: TC Effectiveness
A2: ='Defect Ranks'!A4 -> R4101 A13+A14 OSV | B2: ='Defect Ranks'!D4 -> 490 | C2: ='Defect Ranks'!L4 -> 0 | D2: =B2/C2*100 -> #DIV/0! | E2: ='Defect Ranks'!E4 -> 0 | F2: ='Defect Ranks'!G4 -> 0
A3: ='Defect Ranks'!A5 -> R7301 A12+A14 OSV | B3: ='Defect Ranks'!D5 -> 490 | C3: ='Defect Ranks'!L5 -> 2 | D3: =C3/B3*100 -> 0.40816327 | E3: ='Defect Ranks'!E5 -> 0 | F3: ='Defect Ranks'!G5 -> 0
A4: ='Defect Ranks'!A6 -> R4101 A13+A14 OSV | B4: ='Defect Ranks'!D6 -> 12736 | C4: ='Defect Ranks'!L6 -> 72 | D4: =C4/B4*100 -> 0.56532663 | E4: ='Defect Ranks'!E6 -> 0 | F4: ='Defect Ranks'!G6 -> 0
A5: ='Defect Ranks'!A7 -> R7401 A12+A14 OSV | B5: ='Defect Ranks'!D7 -> 12000 | C5: ='Defect Ranks'!L7 -> 84 | D5: =C5/B5*100 -> 0.7 | E5: ='Defect Ranks'!E7 -> 0 | F5: ='Defect Ranks'!G7 -> 0
A6: ='Defect Ranks'!A8 -> R7402 A12+A14 OSV | B6: ='Defect Ranks'!D8 -> 4022 | C6: ='Defect Ranks'!L8 -> 8 | D6: =C6/B6*100 -> 0.19890602 | E6: ='Defect Ranks'!E8 -> 0 | F6: ='Defect Ranks'!G8 -> 0
A7: ='Defect Ranks'!A9 -> R7411 A13+A14 OSV | B7: ='Defect Ranks'!D9 -> 10790 | C7: ='Defect Ranks'!L9 -> 34 | D7: =C7/B7*100 -> 0.31510658 | E7: ='Defect Ranks'!E9 -> 3212 | F7: ='Defect Ranks'!G9 -> 2 | G7: =F7/E7 -> 0.00062266501
A8: ='Defect Ranks'!A10 -> R7403 A12+A14 OSV | B8: ='Defect Ranks'!D10 -> 4020 | C8: ='Defect Ranks'!L10 -> 24 | D8: =C8/B8*100 -> 0.59701493 | E8: ='Defect Ranks'!E10 -> 0 | F8: ='Defect Ranks'!G10 -> 0
A9: ='Defect Ranks'!A11 -> R7412 A13+ A14 OSV | B9: ='Defect Ranks'!D11 -> 10502 | C9: ='Defect Ranks'!L11 -> 63 | D9: =C9/B9*100 -> 0.59988574 | E9: ='Defect Ranks'!E11 -> 3500 | F9: ='Defect Ranks'!G11 -> 2 | G9: =F9/E9 -> 0.00057142857
A10: ='Defect Ranks'!A12 -> R7404 A12+ A14 OSV | B10: ='Defect Ranks'!D12 -> 4016 | C10: ='Defect Ranks'!L12 -> 27 | D10: =C10/B10*100 -> 0.67231076 | E10: ='Defect Ranks'!E12 -> 1600 | F10: ='Defect Ranks'!G12 -> 1 | G10: =F10/E10 -> 0.000625
A11: ='Defect Ranks'!A13 -> R7413 A13+ A14 OSV | B11: ='Defect Ranks'!D13 -> 9478 | C11: ='Defect Ranks'!L13 -> 78 | D11: =C11/B11*100 -> 0.82295843 | E11: ='Defect Ranks'!E13 -> 4524 | F11: ='Defect Ranks'!G13 -> 5 | G11: =F11/E11 -> 0.0011052166
A12: ='Defect Ranks'!A14 -> R7405 A12+ A14 OSV | B12: ='Defect Ranks'!D14 -> 4016 | C12: ='Defect Ranks'!L14 -> 21 | D12: =C12/B12*100 -> 0.52290837 | E12: ='Defect Ranks'!E14 -> 2000 | F12: ='Defect Ranks'!G14 -> 3 | G12: =F12/E12 -> 0.0015
A13: ='Defect Ranks'!A15 -> R7414 A13+ A14 OSV | B13: ='Defect Ranks'!D15 -> 9002 | C13: ='Defect Ranks'!L15 -> 68 | D13: =C13/B13*100 -> 0.75538769 | E13: ='Defect Ranks'!E15 -> 5000 | F13: ='Defect Ranks'!G15 -> 1 | G13: =F13/E13 -> 0.0002
A14: ='Defect Ranks'!A16 -> R1591 A14+ A15 OSV | B14: ='Defect Ranks'!D16 -> 9608 | C14: ='Defect Ranks'!L16 -> 137 | D14: =C14/B14*100 -> 1.4258951 | E14: ='Defect Ranks'!E16 -> 2988 | F14: ='Defect Ranks'!G16 -> 8 | G14: =F14/E14 -> 0.0026773762
A15: ='Defect Ranks'!A17 -> R7406 A12+ A14 OSV | B15: ='Defect Ranks'!D17 -> 3000 | C15: ='Defect Ranks'!L17 -> 8 | D15: =C15/B15*100 -> 0.26666667 | E15: ='Defect Ranks'!E17 -> 3000 | F15: ='Defect Ranks'!G17 -> 1 | G15: =F15/E15 -> 0.00033333333
A16: ='Defect Ranks'!A18 -> R7415 A13+ A14 OSV | B16: ='Defect Ranks'!D18 -> 8209 | C16: ='Defect Ranks'!L18 -> 53 | D16: =C16/B16*100 -> 0.64563284 | E16: ='Defect Ranks'!E18 -> 5793 | F16: ='Defect Ranks'!G18 -> 2 | G16: =F16/E16 -> 0.00034524426
A17: ='Defect Ranks'!A19 -> R7407 A12+ A14 OSV | B17: ='Defect Ranks'!D19 -> 2750 | C17: ='Defect Ranks'!L19 -> 36 | D17: =C17/B17*100 -> 1.3090909 | E17: ='Defect Ranks'!E19 -> 3250 | F17: ='Defect Ranks'!G19 -> 3 | G17: =F17/E17 -> 0.00092307692
A18: ='Defect Ranks'!A20 -> R7416 A13+ A14 OSV | B18: ='Defect Ranks'!D20 -> 6043 | C18: ='Defect Ranks'!L20 -> 75 | D18: =C18/B18*100 -> 1.2411054 | E18: ='Defect Ranks'!E20 -> 7959 | F18: ='Defect Ranks'!G20 -> 2 | G18: =F18/E18 -> 0.00025128785
A19: ='Defect Ranks'!A21 -> R7408 A12+ A14 OSV | B19: ='Defect Ranks'!D21 -> 3500 | C19: ='Defect Ranks'!L21 -> 44 | D19: =C19/B19*100 -> 1.2571429 | E19: ='Defect Ranks'!E21 -> 2500 | F19: ='Defect Ranks'!G21 -> 2 | G19: =F19/E19 -> 0.0008
A20: ='Defect Ranks'!A22 -> R7417 A13+ A14 OSV | B20: ='Defect Ranks'!D22 -> 3000 | C20: ='Defect Ranks'!L22 -> 51 | D20: =C20/B20*100 -> 1.7 | E20: ='Defect Ranks'!E22 -> 5419 | F20: ='Defect Ranks'!G22 -> 1 | G20: =F20/E20 -> 0.00018453589
A21: ='Defect Ranks'!A23 -> R7409 Additional LRT OSV A12+A14 SU2 | B21: ='Defect Ranks'!D23 -> 3442 | C21: ='Defect Ranks'!L23 -> 66 | D21: =C21/B21*100 -> 1.9174898 | E21: ='Defect Ranks'!E23 -> 2992 | F21: ='Defect Ranks'!G23 -> 1 | G21: =F21/E21 -> 0.0003342246
A24: Iteration | B24: Manual TC Effectiveness | C24: Automation TC Effectiveness
A25: =A2 -> R4101 A13+A14 OSV | B25: 0 | C25: =G2 -> 0
A26: =A3 -> R7301 A12+A14 OSV | B26: =D3 -> 0.40816327 | C26: =G3 -> 0
A27: =A4 -> R4101 A13+A14 OSV | B27: =D4 -> 0.56532663 | C27: =G4 -> 0
A28: =A5 -> R7401 A12+A14 OSV | B28: =D5 -> 0.7 | C28: =G5 -> 0
A29: =A6 -> R7402 A12+A14 OSV | B29: =D6 -> 0.19890602 | C29: =G6 -> 0
A30: =A7 -> R7411 A13+A14 OSV | B30: =D7 -> 0.31510658 | C30: =G7 -> 0.00062266501
A31: =A8 -> R7403 A12+A14 OSV | B31: =D8 -> 0.59701493 | C31: =G8 -> 0
A32: =A9 -> R7412 A13+ A14 OSV | B32: =D9 -> 0.59988574 | C32: =G9 -> 0.00057142857
A33: =A10 -> R7404 A12+ A14 OSV | B33: =D10 -> 0.67231076 | C33: =G10 -> 0.000625
A34: =A11 -> R7413 A13+ A14 OSV | B34: =D11 -> 0.82295843 | C34: =G11 -> 0.0011052166
A35: =A12 -> R7405 A12+ A14 OSV | B35: =D12 -> 0.52290837 | C35: =G12 -> 0.0015
A36: =A13 -> R7414 A13+ A14 OSV | B36: =D13 -> 0.75538769 | C36: =G13 -> 0.0002
A37: =A14 -> R1591 A14+ A15 OSV | B37: =D14 -> 1.4258951 | C37: =G14 -> 0.0026773762
... A44: =A21 -> R7409 Additional LRT OSV A12+A14 SU2 | B44: =D21 -> 1.9174898 | C44: =G21 -> 0.0003342246

Sheet 4 MSR
K1: IVI Validation - October Planned Deliveries
K2: # | L2: Sub Project Name | M2: Deliveries | N2: Planned End Date | O2: Actual End Date | P2: Status
B3: LRT | C3: A13+A14 | D3: A12+A14 | E3: A13+A14 | J3: Oct | K3: 1 | L3: LRT OSV PF23 | M3: A14-13VF R7414 | N3: 45937 | O3: 45937 | P3: Completed
B4: Cycle | C4: Cycle 2 | D4: Cycle 3 | E4: Cycle 3
B5: Iteration | C5: R7412 | D5: R7404 | E5: R7413 | K5: IVI Validation - November Planned Deliveries
B6: Total TC Plan / Executed | C6: 14002 | D6: =SUM(D7:D8) -> 5616 | E6: =SUM(E7:E8) -> 14002 | K6: # | L6: Sub Project Name | M6: Deliveries | N6: Planned End Date | O6: Actual End Date | P6: Status
B7: Manual TC Executed | C7: 10502 | D7: 4016 | E7: 9478 | K7: 1 | L7: LRT OSV PF23 | M7: A15-14VF R1591 | N7: 45968 | O7: 45968 | P7: Completed
B8: Automation TC Executed | C8: 3500 | D8: 1600 | E8: 4524 | J8: Nov | K8: 2 | L8: LRT OSV PF23 | M8: A14-12VF-SU1-1 R7406 | N8: 45971 | O8: 45971 | P8: Completed
B9: Manual Defect Raised | C9: 63 | D9: 25 | E9: 78 | K9: 3 | L9: LRT OSV PF23 | M9: A14-13VF-SU1-1 R7415 | N9: 45982 | O9: 45982 | P9: Completed
B10: Automation Defect Raised | C10: 2 | D10: 1 | E10: 5
B11: Total Defect Raised | C11: =SUM(C9:C10) -> 65 | D11: =SUM(D9:D10) -> 26 | E11: =SUM(E9:E10) -> 83 | K11: IVI Validation - December Planned Deliveries
B12: Manual Team defect density | C12: =C9/C7 -> 0.0059988574 | D12: =D9/D7 -> 0.0062250996 | E12: =E9/E7 -> 0.0082295843 | K12: # | L12: Sub Project Name | M12: Deliveries | N12: Planned End Date | O12: Actual End Date | P12: Status
B13: Automation Team defect density | C13: =C10/C8 -> 0.00057142857 | D13: =D10/D8 -> 0.000625 | E13: =E10/E8 -> 0.0011052166 | J13: Dec | K13: 1 | L13: LRT OSV PF23 | M13: A14-12VF-SU1-2 R7407 | N13: 46011 | O13: 46011 | P13: Completed
B15: Iteration | D15: TC | E15: Total Defects | F15: S Rank | G15: A Rank | H15: B Rank | I15: C Rank
B16: OSV A13+A14 | C16: R7412 Cycle 2 | D16: 14002 | E16: =SUM(F16:I16) -> 65 | F16: =2+3 -> 5 | G16: 6 | H16: 32 | I16: 22
B17: OSV A12+A14 | C17: R7404 Cycle 3 | D17: 5616 | E17: =SUM(F17:I17) -> 29 | F17: =1+1 -> 2 | G17: 3 | H17: 14 | I17: 10
B18: OSV A13+A14 | C18: R7413 Cycle 3 | D18: 14002 | E18: =SUM(F18:I18) -> 83 | F18: 3 | G18: 18 | H18: 40 | I18: 22
B19: Total | D19: =SUM(D14:D18) -> 33620 | E19: =SUM(E14:E18) -> 177 | F19: =SUM(F14:F18) -> 10 | G19: =SUM(G14:G18) -> 27 | H19: =SUM(H14:H18) -> 86 | I19: =SUM(I14:I18) -> 54

Sheet WSR
A1: Phase | B1: Activity | C1: Planned Start Date | D1: Planned End Date | E1: Status | F1: Calendar Week | G1: CW49 | L1: CW50 | Q1: CW51 | W1: CW52 | AB1: CW 01 | AG1: CW 02 | AL1: CW 03 | AQ1: CW 03
F2: Month | G2: Dec'25 | AE2: Jan'26
F3: Days | G3: 1 | H3: 2 | I3: 3 | J3: 4 | K3: 5 | L3: 8 | M3: 9 | N3: 10 | O3: 11 | P3: 12 | Q3: 15 | R3: 16 | S3: 17 | T3: 18 | U3: 19 | V3: 20 | W3: 22 | X3: 23 | Y3: 24 | Z3: 25 | AA3: 26 | AB3: 29 | AC3: 30 | AD3: 31 | AE3: 1 | AF3: 2 | AG3: 5 | AH3: 6 | AI3: 7 | AJ3: 8 | AK3: 9 | AL3: 12 | AM3: 13 | AN3: 14 | AO3: 15 | AP3: 16 | AQ3: 19 | AR3: 20 | AS3: 21 | AT3: 22 | AU3: 23
A4: A14-12VF-SU1-2
A5: A14-12VF-SU1-2 | B5: A12+A14 | C5: 46007 | D5: 46011 | E5: Planned
A6: A14-13VF-SU1-2
A7: A14-13VF-SU1-2 | B7: A13+A14 | C7: 46028 | D7: 46041 | E7: Planned

Sheet Team
A1: Name | B1: Team | D1: Assignee | E1: Team | F1: Draft | G1: Waiting | H1: IN INVESTIGATING | I1: IN WORK | J1: IN INTEGRATION REVIEW | K1: CLOSE CONFIRMATION | L1: INVESTIGATING OUTSIDE | M1: [IN INVESTIGATING]APPLY FOR CLOSE | N1: [IN WORK]APPLY FOR CLOSE | O1: BLOCK FIXING VALIDATION | P1: CLOSED | Q1: T: | R1: T:
A2: KPT Abhinandan Bankar | B2: Val | D2: HM Yunan Cai | E2: =VLOOKUP(D2,A:B,2,0) -> HM | F2: 0 | G2: 0 | H2: 0 | I2: 0 | J2: 0 | K2: 0 | L2: 1 | M2: 0 | N2: 0 | O2: 0 | P2: 0 | Q2: 1 | R2: 1
A3: KPT Achal Saraiya | B3: Dev | D3: KPT Abhaya Samantaray | E3: =VLOOKUP(D3,A:B,2,0) -> Dev | F3: 0 | G3: 0 | H3: 1 | I3: 0 | J3: 0 | K3: 0 | L3: 0 | M3: 0 | N3: 0 | O3: 0 | P3: 0 | Q3: 1 | R3: 1
A4: KPT Adarsh Kp | B4: Val | D4: KPT Adarsh Kp | E4: =VLOOKUP(D4,A:B,2,0) -> Val | F4: 2 | G4: 0 | H4: 0 | I4: 0 | J4: 0 | K4: 0 | L4: 0 | M4: 0 | N4: 0 | O4: 0 | P4: 2 | Q4: 4 | R4: 4
A5: KPT Amir Mulla2 | B5: Dev | D5: KPT Affan Ather | E5: =VLOOKUP(D5,A:B,2,0) -> Dev | F5: 0 | G5: 0 | H5: 0 | I5: 0 | J5: 0 | K5: 0 | L5: 1 | M5: 1 | N5: 0 | O5: 0 | P5: 0 | Q5: 2 | R5: 2
A6: KPT Aniket Chaudhari | B6: Val | D6: KPT Ajinkya Khanwilkar | E6: =VLOOKUP(D6,A:B,2,0) -> Dev | F6: 0 | G6: 0 | H6: 0 | I6: 0 | J6: 0 | K6: 0 | L6: 0 | M6: 0 | N6: 1 | O6: 0 | P6: 0 | Q6: 1 | R6: 1
A7: KPT Apurva Thombare | B7: Val | D7: KPT Akhilesh B S | E7: =VLOOKUP(D7,A:B,2,0) -> Dev | F7: 0 | G7: 0 | H7: 1 | I7: 0 | J7: 0 | K7: 0 | L7: 0 | M7: 0 | N7: 0 | O7: 0 | P7: 0 | Q7: 1 | R7: 1
A8: KPT Arpitha S | B8: Val | D8: KPT Amit Dixit | E8: =VLOOKUP(D8,A:B,2,0) -> Dev | F8: 0 | G8: 3 | H8: 1 | I8: 0 | J8: 0 | K8: 0 | L8: 0 | M8: 1 | N8: 2 | O8: 0 | P8: 0 | Q8: 7 | R8: 7
A9: KPT Arpit Nayak | B9: Val | D9: KPT Amrit Raj | E9: =VLOOKUP(D9,A:B,2,0) -> Val | F9: 2 | G9: 0 | H9: 0 | I9: 0 | J9: 0 | K9: 0 | L9: 0 | M9: 0 | N9: 0 | O9: 0 | P9: 0 | Q9: 2 | R9: 2
A10: KPT Ashish Kadam | B10: Dev | D10: KPT Aniket Chaudhari | E10: =VLOOKUP(D10,A:B,2,0) -> Val | F10: 4 | G10: 0 | H10: 0 | I10: 0 | J10: 0 | K10: 0 | L10: 0 | M10: 0 | N10: 0 | O10: 0 | P10: 1 | Q10: 5 | R10: 5
A11: KPT Ashwini Karale | B11: Val | D11: KPT Apurva Thombare | E11: =VLOOKUP(D11,A:B,2,0) -> Val | F11: 1 | G11: 0 | H11: 0 | I11: 0 | J11: 0 | K11: 0 | L11: 0 | M11: 0 | N11: 0 | O11: 0 | P11: 0 | Q11: 1 | R11: 1
A12: KPT Ayush Mishra | B12: Val | D12: KPT Arpitha S | E12: =VLOOKUP(D12,A:B,2,0) -> Val | F12: 4 | G12: 0 | H12: 0 | I12: 0 | J12: 0 | K12: 0 | L12: 0 | M12: 0 | N12: 0 | O12: 0 | P12: 2 | Q12: 6 | R12: 6
A13: KPT Ayush Singh | B13: Val | D13: KPT Arpit Nayak | E13: =VLOOKUP(D13,A:B,2,0) -> Val | F13: 0 | G13: 0 | H13: 0 | I13: 0 | J13: 0 | K13: 0 | L13: 0 | M13: 0 | N13: 0 | O13: 0 | P13: 3 | Q13: 3 | R13: 3
... A52: KPT Ajinkya Khanwilkar | B52: Dev | D52: KPT Sunita Khilare | E52: =VLOOKUP(D52,A:B,2,0) -> Dev | F52: 0 | G52: 23 | H52: 0 | I52: 0 | J52: 2 | K52: 0 | L52: 0 | M52: 1 | N52: 0 | O52: 0 | P52: 0 | Q52: 26 | R52: 178
A53: KPT Amit Dixit | B53: Dev | D53: KPT Suraj Shimpi | E53: =VLOOKUP(D53,A:B,2,0) -> Dev | F53: 0 | G53: 0 | H53: 2 | I53: 0 | J53: 0 | K53: 0 | L53: 0 | M53: 0 | N53: 0 | O53: 0 | P53: 0 | Q53: 2
A54: KPT Ashish Wadatkar | B54: Dev | D54: KPT Vishal Sakore | E54: =VLOOKUP(D54,A:B,2,0) -> Dev | F54: 0 | G54: 0 | H54: 1 | I54: 0 | J54: 0 | K54: 0 | L54: 0 | M54: 0 | N54: 0 | O54: 0 | P54: 0 | Q54: 1
A55: KPT Ashok R | B55: Dev | D55: KPT Yashpal M | E55: =VLOOKUP(D55,A:B,2,0) -> Dev | F55: 0 | G55: 0 | H55: 0 | I55: 0 | J55: 0 | K55: 0 | L55: 1 | M55: 0 | N55: 0 | O55: 0 | P55: 0 | Q55: 1
A56: KPT Chirag Gandhi | B56: Dev | D56: KPT Yogeshwari Saratkar | E56: =VLOOKUP(D56,A:B,2,0) -> Val | F56: 0 | G56: 0 | H56: 0 | I56: 0 | J56: 0 | K56: 0 | L56: 0 | M56: 0 | N56: 0 | O56: 0 | P56: 1 | Q56: 1
A57: KPT Gaurav Dhande | B57: Dev | D57: Total Unique Issues: | F57: 41 | G57: 34 | H57: 23 | I57: 2 | J57: 10 | K57: 5 | L57: 10 | M57: 9 | N57: 4 | O57: 5 | P57: 35 | Q57: 178
A58: KPT Gayatri Rokade | B58: Dev
A59: KPT Janhavee Shrungare | B59: Dev
A60: KPT Jithu Sidhardhan | B60: Dev
A61: KPT Juhi Ahire | B61: Dev
A62: KPT Onkar More | B62: Dev
A63: KPT Pavan Katta | B63: Dev
A64: KPT Piyush Kumar | B64: Val
A65: KPT Prasad Nalawade | B65: Dev
A66: KPT Pratik Chawke | B66: Dev
A67: KPT Rahul Pisal | B67: Dev
A68: KPT Rajesh Av | B68: Dev
A69: KPT Renuka M | B69: Dev
... A144: KPT Yashpal M | B144: Dev

Sheet WSR Graph A1214
C2: S.No | D2: Parameter | E2: CW10 | F2: CW11 | G2: CW12
C3: 1 | D3: Cumulative JIRA defect Raised | E3: 324 | F3: 324 | G3: 324
C4: 2 | D4: Closed Defects | E4: 121 | F4: 122 | G4: 124
C5: 3 | D5: Open Defects | E5: =E3-E4 -> 203 | F5: =F3-F4 -> 202 | G5: =G3-G4 -> 200
C6: 3.1 | D6: Open JIRA defect with Dev Team | E6: =E5-SUM(E7:E8) -> 199 | F6: =F5-SUM(F7:F8) -> 198 | G6: =G5-SUM(G7:G8) -> 194
C7: 3.2 | D7: Open JIRA defect with Val Team | E7: 1 | F7: 2 | G7: 2 | Q7: 26
C8: 3.3 | D8: Open JIRA defect with Honda Team | E8: 3 | F8: 2 | G8: 4
C11: S.No | D11: Parameter | E11: CW10 | F11: CW11 | G11: CW12
C12: 1 | D12: Cumulative JIRA defect Raised | E12: 66 | F12: 66 | G12: 66
C13: 2 | D13: Closed Defects | E13: 0 | F13: 0 | G13: 0
C14: 3 | D14: Open Defects | E14: =E12-E13 -> 66 | F14: =F12-F13 -> 66 | G14: =G12-G13 -> 66
C15: 3.1 | D15: Open JIRA defect with Dev Team | E15: =E14-SUM(E16:E17) -> 66 | F15: =F14-SUM(F16:F17) -> 66 | G15: =G14-SUM(G16:G17) -> 62
C16: 3.2 | D16: Open JIRA defect with Val Team | E16: 0 | F16: 0 | G16: 4
C17: 3.3 | D17: Open JIRA defect with Honda Team | E17: 0 | F17: 0 | G17: 0
D21: LRT OSV A12+A14 Overall Defect Status - Tabby_Jira
D22: LRT OSV A14-12VF-SU2-1 R7408 Defect Status - Tabby_Jira

Sheet WSR Graph A1314
D1: Overall
C2: S.No | D2: Parameter | E2: CW10 | F2: CW11 | G2: CW12
A3: 235 | C3: 1 | D3: Cumulative JIRA defect Raised | E3: 525 | F3: 550 | G3: 564
A4: 145 | C4: 2 | D4: Closed Defects | E4: 222 | F4: 224 | G4: 234
C5: 3 | D5: Open Defects | E5: =E3-E4 -> 303 | F5: =F3-F4 -> 326 | G5: =G3-G4 -> 330
C6: 3.1 | D6: Open JIRA defect with Dev Team | E6: =E5-SUM(E7:E8) -> 287 | F6: =F5-SUM(F7:F8) -> 317 | G6: =G5-SUM(G7:G8) -> 319
C7: 3.2 | D7: Open JIRA defect with Val Team | E7: 11 | F7: 4 | G7: 8
C8: 3.3 | D8: Open JIRA defect with Honda Team | E8: 5 | F8: 5 | G8: 3
D10: R7418
C11: S.No | D11: Parameter | E11: CW10 | F11: CW11 | G11: CW12
C12: 1 | D12: Cumulative JIRA defect Raised | E12: 0 | F12: 0 | G12: 0
C13: 2 | D13: Closed Defects | E13: 0 | F13: 0 | G13: 0
C14: 3 | D14: Open Defects | E14: =E12-E13 -> 0 | F14: =F12-F13 -> 0 | G14: =G12-G13 -> 0
C15: 3.1 | D15: Open JIRA defect with Dev Team | E15: =E14-SUM(E16:E17) -> 0 | F15: =F14-SUM(F16:F17) -> 0 | G15: =G14-SUM(G16:G17) -> 0
C16: 3.2 | D16: Open JIRA defect with Val Team | E16: 0 | F16: 0 | G16: 0
C17: 3.3 | D17: Open JIRA defect with Honda Team | E17: 0 | F17: 0 | G17: 0
D40: 11 | E40: 6 | F40: 31 | G40: 22 | H40: 0 | I40: 0 | J40: 0 | K40: 0 | L40: 0 | M40: 0 | N40: 6 | O40: 16 | P40: 17 | Q40: 4 | R40: 10 | S40: 52 | T40: 38 | U40: 2 | V40: 19 | W40: 36 | X40: 21

Sheet WSR Graph A1415
C1: Overall
B2: S.No | C2: Parameter | D2: CW10 | E2: CW11 | F2: CW12
B3: 1 | C3: Cumulative JIRA defect Raised | D3: 137 | E3: 137 | F3: 175
B4: 2 | C4: Closed Defects | D4: 25 | E4: 33 | F4: 36
B5: 3 | C5: Open Defects | D5: =D3-D4 -> 112 | E5: =E3-E4 -> 104 | F5: =F3-F4 -> 139
B6: 3.1 | C6: Open JIRA defect with Dev Team | D6: =D5-SUM(D7:D8) -> 101 | E6: =E5-SUM(E7:E8) -> 98 | F6: =F5-SUM(F7:F8) -> 131
B7: 3.2 | C7: Open JIRA defect with Val Team | D7: 9 | E7: 6 | F7: 5
B8: 3.3 | C8: Open JIRA defect with Honda Team | D8: 2 | E8: 0 | F8: 3
C10: R1503
B11: S.No | C11: Parameter | D11: CW10 | E11: CW11 | F11: CW12
B12: 1 | C12: Cumulative JIRA defect Raised | D12: 0 | E12: 0 | F12: 38
B13: 2 | C13: Closed Defects | D13: 0 | E13: 0 | F13: 0
B14: 3 | C14: Open Defects | D14: =D12-D13 -> 0 | E14: =E12-E13 -> 0 | F14: =F12-F13 -> 38
B15: 3.1 | C15: Open JIRA defect with Dev Team | D15: =D14-SUM(D16:D17) -> 0 | E15: =E14-SUM(E16:E17) -> 0 | F15: =F14-SUM(F16:F17) -> 38
B16: 3.2 | C16: Open JIRA defect with Val Team | D16: 0 | E16: 0 | F16: 0
B17: 3.3 | C17: Open JIRA defect with Honda Team | D17: 0 | E17: 0 | F17: 0
C40: 11 | D40: 6 | E40: 31 | F40: 22 | G40: 0 | H40: 0 | I40: 0 | J40: 0 | K40: 0 | L40: 0 | M40: 6 | N40: 16 | O40: 17 | P40: 4 | Q40: 10 | R40: 52 | S40: 38 | T40: 2 | U40: 19 | V40: 36 | W40: 21

Sheet PGM Review
B1: LRT OSV
B2: Execution Iteration | D2: Test Cases Executed | K2: %
A3: Iteration | B3: Iteration | C3: Month | D3: Total TC | E3: Manual | H3: Automation | K3: Manual
E4: L3 | F4: L4 | G4: Manual Total | H4: L3 | I4: L4 | J4: Automation Total | K4: Manual %
A5: R4101 | B5: R4101 A13+A14 OSV | C5: 45734 | D5: 490 | E5: 221 | F5: =G5-E5 -> 269 | G5: 490 | H5: 0 | I5: =J5-H5 -> 0 | J5: =D5-G5 -> 0 | K5: =G5/D5 -> 1
A6: R7301 | B6: R7301 A12+A14 OSV | C6: 45742 | D6: 490 | E6: 221 | F6: =G6-E6 -> 269 | G6: 490 | H6: 0 | I6: =J6-H6 -> 0 | J6: =D6-G6 -> 0 | K6: =G6/D6 -> 1
A7: R4101 | B7: R4101 A13+A14 OSV | C7: 45765 | D7: 12736 | E7: 6720 | F7: =G7-E7 -> 6016 | G7: 12736 | H7: 0 | I7: =J7-H7 -> 0 | J7: =D7-G7 -> 0 | K7: =G7/D7 -> 1
A8: R7401 | B8: R7401 A12+A14 OSV | C8: 45790 | D8: 12000 | E8: 6399 | F8: =G8-E8 -> 5601 | G8: 12000 | H8: 0 | I8: =J8-H8 -> 0 | J8: =D8-G8 -> 0 | K8: =G8/D8 -> 1
A9: R7402 | B9: R7402 A12+A14 OSV | C9: 45814 | D9: 4022 | E9: 2399 | F9: =G9-E9 -> 1623 | G9: 4022 | H9: 0 | I9: =J9-H9 -> 0 | J9: =D9-G9 -> 0 | K9: =G9/D9 -> 1
A10: R7411 | B10: R7411 A13+A14 OSV | C10: 45833 | D10: 14002 | E10: 6408 | F10: =G10-E10 -> 4382 | G10: 10790 | H10: 1832 | I10: =J10-H10 -> 1380 | J10: =D10-G10 -> 3212 | K10: =G10/D10 -> 0.7706042
A11: R7403 | B11: R7403 A12+A14 OSV | C11: 45840 | D11: 4020 | E11: 2397 | F11: =G11-E11 -> 1623 | G11: 4020 | H11: 0 | I11: =J11-H11 -> 0 | J11: =D11-G11 -> 0 | K11: =G11/D11 -> 1
A12: R7412 | B12: R7412 A13+ A14 OSV | C12: 45863 | D12: 14002 | E12: 6028 | F12: =G12-E12 -> 4474 | G12: 10502 | H12: 2388 | I12: =J12-H12 -> 1112 | J12: =D12-G12 -> 3500 | K12: =G12/D12 -> 0.75003571
A13: R7404 | B13: R7404 A12+ A14 OSV | C13: 45868 | D13: 5616 | E13: 2396 | F13: =G13-E13 -> 1620 | G13: 4016 | H13: 918 | I13: =J13-H13 -> 682 | J13: =D13-G13 -> 1600 | K13: =G13/D13 -> 0.71509972
A14: R7413 | B14: R7413 A13+ A14 OSV | C14: 45890 | D14: 14002 | E14: 5631 | F14: =G14-E14 -> 3847 | G14: 9478 | H14: 2785 | I14: =J14-H14 -> 1739 | J14: =D14-G14 -> 4524 | K14: =G14/D14 -> 0.6769033
A15: R7405 | B15: R7405 A12+ A14 OSV | C15: 45919 | D15: 6016 | E15: 2377 | F15: =G15-E15 -> 1639 | G15: 4016 | H15: 1135 | I15: =J15-H15 -> 865 | J15: =D15-G15 -> 2000 | K15: =G15/D15 -> 0.66755319
B16: Total | D16: =SUM(D5:D15) -> 87396 | E16: =SUM(E5:E15) -> 41197 | F16: =SUM(F5:F15) -> 31363 | G16: =SUM(G5:G15) -> 72560 | H16: =SUM(H5:H15) -> 9058 | I16: =SUM(I5:I15) -> 5778 | J16: =SUM(J5:J15) -> 14836

Sheet PV Analysis
A1: Project name | B1: (Multiple Items) | D1: link
A2: Issue Type | B2: (Multiple Items)
A4: Count of Created | B4: Column Labels
B5: <3/13/2023 | C5: 2023 | D5: 2024 | E5: 2025 | F5: 2026 | G5: Grand Total | P5: During OSV
O6: All | P6: April 2025 till Feb2026
U7: A13 | X7: OSV | AA7: OSV
A8: Row Labels | N8: Name | P8: FY2025-26 | R8: PJ02_DEF_01 | S8: Defect Count | U8: PJ03_DEF_00 | V8: Defect Count | X8: PJ04_DEF_00 | Y8: Defect Count | AA8: PJ05_DEF_00 | AB8: Defect Count
A9: kpt_chaudhari_an | E9: 39 | F9: 20 | G9: 59 | N9: kpt_chaudhari_an | O9: 59 | P9: 59 | R9: kpt_tehra_ma | S9: 1 | U9: kpt_reddy_ke | V9: 25 | X9: kpt_lucky_md | Y9: 87 | AA9: kpt_patil_di | AB9: 14
A10: kpt_gahile_pr | E10: 42 | F10: 11 | G10: 53 | N10: kpt_gahile_pr | O10: 53 | P10: 53 | R10: kpt_thombare_ap | S10: 1 | U10: kpt_rane_sh | V10: 20 | X10: kpt_mishra_ay | Y10: 70 | AA10: kpt_gahile_pr | AB10: 8
A11: kpt_gaikwad_pr | D11: 5 | E11: 48 | F11: 13 | G11: 66 | N11: kpt_gaikwad_pr | O11: 66 | P11: 61 | U11: kpt_patil_di | V11: 19 | X11: kpt_patil_di | Y11: 62 | AA11: kpt_lucky_md | AB11: 8
A12: kpt_gunjal_ji | C12: 1 | D12: 5 | E12: 26 | F12: 7 | G12: 39 | N12: kpt_gunjal_ji | O12: 39 | P12: 32 | U12: kpt_nayak_ar | V12: 9 | X12: kpt_gaikwad_pr | Y12: 55 | AA12: kpt_mishra_ay | AB12: 7
A13: kpt_kumar_pi | D13: 1 | E13: 27 | F13: 2 | G13: 30 | N13: kpt_kumar_pi | O13: 30 | P13: 28 | U13: kpt_tehra_ma | V13: 9 | X13: kpt_tehra_ma | Y13: 54 | AA13: kpt_chaudhari_an | AB13: 6
A14: kpt_lucky_md | D14: 1 | E14: 80 | F14: 19 | G14: 100 | N14: kpt_lucky_md | O14: 100 | P14: 95 | U14: kpt_gunjal_ji | V14: 7 | X14: kpt_chaudhari_an | Y14: 53 | AA14: kpt_gaikwad_pr | AB14: 6
A15: kpt_mishra_ay | D15: 2 | E15: 62 | F15: 17 | G15: 81 | N15: kpt_mishra_ay | O15: 81 | P15: 77 | U15: kpt_kumar_pi | V15: 6 | X15: kpt_gahile_pr | Y15: 45 | AA15: kpt_tehra_ma | AB15: 5
A16: kpt_nayak_ar | D16: 1 | E16: 31 | F16: 3 | G16: 35 | N16: kpt_nayak_ar | O16: 35 | P16: 31 | U16: kpt_gaikwad_pr | V16: 5 | X16: kpt_rane_sh | Y16: 35 | AA16: kpt_gunjal_ji | AB16: 4
A17: kpt_patil_di | C17: 3 | D17: 10 | E17: 49 | F17: 33 | G17: 95 | N17: kpt_patil_di | O17: 95 | P17: 82 | U17: kpt_lucky_md | V17: 5 | X17: kpt_walke_sh | Y17: 33 | AA17: kpt_nayak_ar | AB17: 4
A18: kpt_raj_am | E18: 9 | F18: 15 | G18: 24 | N18: kpt_raj_am | O18: 24 | P18: 24 | U18: kpt_mishra_ay | V18: 4 | X18: kpt_thombare_ap | Y18: 30 | AA18: kpt_reddy_ke | AB18: 4
A19: kpt_rajmane_go | E19: 8 | F19: 12 | G19: 20 | N19: kpt_rajmane_go | O19: 20 | P19: 20 | U19: kpt_reddimalla_pr | V19: 4 | X19: kpt_gunjal_ji | Y19: 28 | AA19: kpt_walke_sh | AB19: 4
A20: kpt_rane_sh | D20: 4 | E20: 50 | F20: 4 | G20: 58 | N20: kpt_rane_sh | O20: 58 | P20: 48 | U20: kpt_thombare_ap | V20: 4 | X20: kpt_reddy_ke | Y20: 27 | AA20: kpt_kumar_pi | AB20: 3
A21: kpt_reddimalla_pr | D21: 1 | E21: 24 | F21: 5 | G21: 30 | N21: kpt_reddimalla_pr | O21: 30 | P21: 28 | U21: kpt_walke_sh | V21: 3 | X21: kpt_reddimalla_pr | Y21: 24 | AA21: kpt_rane_sh | AB21: 3
A22: kpt_reddy_ke | C22: 3 | D22: 7 | E22: 40 | F22: 6 | G22: 56 | N22: kpt_reddy_ke | O22: 56 | P22: 44 | X22: kpt_nayak_ar | Y22: 22 | AA22: kpt_raj_am | AB22: 2
A23: kpt_tehra_ma | C23: 3 | D23: 5 | E23: 50 | F23: 11 | G23: 69 | N23: kpt_tehra_ma | O23: 69 | P23: 59 | X23: kpt_raj_am | Y23: 22 | AA23: kpt_reddimalla_pr | AB23: 2
A24: kpt_thombare_ap | C24: 1 | D24: 5 | E24: 25 | F24: 6 | G24: 37 | N24: kpt_thombare_ap | O24: 37 | P24: 31 | X24: kpt_kumar_pi | Y24: 21 | AA24: kpt_thombare_ap | AB24: 2
A25: kpt_walke_sh | C25: 1 | D25: 2 | E25: 29 | F25: 8 | G25: 40 | N25: kpt_walke_sh | O25: 40 | P25: 37 | X25: kpt_rajmane_go | Y25: 20
A26: (blank)
A27: Grand Total | C27: 12 | D27: 49 | E27: 639 | F27: 192 | G27: 892
R28: During OSV
R29: April 2025 till Feb2026 | U29: NEW Defects | X29: Replica
N30: Name | O30: All KPIT till Feb26 | Q30: Name | R30: FY2025-26 | T30: Name | U30: FY2025-26 | W30: Name | X30: FY2025-26
N31: kpt_lucky_md | O31: 100 | Q31: kpt_lucky_md | R31: 95
N32: kpt_patil_di | O32: 95 | P32: Onsite | Q32: kpt_patil_di | R32: 82 | S32: Onsite
N33: kpt_mishra_ay | O33: 81 | Q33: kpt_mishra_ay | R33: 77
N34: kpt_tehra_ma | O34: 69 | Q34: kpt_gaikwad_pr | R34: 61
N35: kpt_gaikwad_pr | O35: 66 | Q35: kpt_tehra_ma | R35: 59
N36: kpt_chaudhari_an | O36: 59 | Q36: kpt_chaudhari_an | R36: 59
N37: kpt_rane_sh | O37: 58 | P37: Defects Team | Q37: kpt_gahile_pr | R37: 53
N38: kpt_reddy_ke | O38: 56 | P38: Defects Team | Q38: kpt_rane_sh | R38: 48 | S38: Defects Team
N39: kpt_gahile_pr | O39: 53 | Q39: kpt_reddy_ke | R39: 44 | S39: Defects Team
N40: kpt_walke_sh | O40: 40 | Q40: kpt_walke_sh | R40: 37
N41: kpt_gunjal_ji | O41: 39 | Q41: kpt_gunjal_ji | R41: 32
...

Sheet A-S Rank
A1: Custom field (Defect Rank) | B1: (Multiple Items)
A3: Count of Created | B3: Column Labels
B4: 2023 | C4: 2024 | D4: 2025 | E4: 2026 | F4: Grand Total
A7: Row Labels
A8: kpt_chaudhari_an | D8: 7 | E8: 1 | F8: 8
A9: kpt_gahile_pr | D9: 7 | E9: 2 | F9: 9
A10: kpt_gaikwad_pr | C10: 1 | D10: 6 | E10: 2 | F10: 9
A11: kpt_gunjal_ji | B11: 1 | C11: 1 | D11: 5 | F11: 7
A12: kpt_kumar_pi | D12: 2 | F12: 2 | G12: Defects Verification
A13: kpt_lucky_md | D13: 9 | E13: 1 | F13: 10 | G13: ***
A14: kpt_mishra_ay | C14: 1 | D14: 11 | E14: 2 | F14: 14 | G14: * *
A15: kpt_nayak_ar | D15: 2 | F15: 2 | G15: Defects Verification
A16: kpt_patil_di | C16: 3 | D16: 5 | E16: 5 | F16: 13
A17: kpt_raj_am | D17: 1 | E17: 2 | F17: 3
A18: kpt_rajmane_go | E18: 2 | F18: 2
A19: kpt_rane_sh | C19: 1 | D19: 5 | E19: 1 | F19: 7 | G19: Defects Verification
A20: kpt_reddimalla_pr | D20: 6 | E20: 1 | F20: 7
A21: kpt_reddy_ke | D21: 1 | F21: 1 | G21: Defects Verification
A22: kpt_tehra_ma | D22: 24 | E22: 4 | F22: 28 | G22: *
A23: kpt_thombare_ap | C23: 5 | D23: 3 | E23: 1 | F23: 9
A24: Grand Total | B24: 1 | C24: 12 | D24: 94 | E24: 24 | F24: 131

Sheet Sheet2
A1: Tester | B1: Total | C1: Not Executed | D1: In Progress | E1: Pass | F1: Fail | G1: Blocked | H1: In Review | I1: Completed | J1: Remaining | K1: Progress | L1: Estimated | M1: Actual | N1: Remaining | O1: Variation | P1: Open | Q1: Closed | R1: Total
A2: KPT Dinesh Patil | B2: 403 | C2: 0% (0) | D2: 0% (0) | E2: 100% (403) | F2: 0% (0) | G2: 0% (0) | H2: 0% (0) | I2: 403 | J2: 0 | K2: 1 | L2: 0 | M2: 1.3673611 | N2: 0 | O2: - | P2: 0 | Q2: 0 | R2: 0
A3: KPT Prachi Gahile | B3: 1866 | C3: 0% (0) | D3: 0% (0) | E3: 96.89% (1808) | F3: 3.11% (58) | G3: 0% (0) | H3: 0% (0) | I3: 1866 | J3: 0 | K3: 1 | L3: 0 | M3: 7.8354167 | N3: 0 | O3: - | P3: 1 | Q3: 3 | R3: 4
A4: KPT Mansi Tehra | B4: 2505 | C4: 0% (0) | D4: 0% (0) | E4: 98.04% (2456) | F4: 1.96% (49) | G4: 0% (0) | H4: 0% (0) | I4: 2505 | J4: 0 | K4: 1 | L4: 0 | M4: 8.1451389 | N4: 0 | O4: - | P4: 5 | Q4: 5 | R4: 10
A5: KPT Apurva Thombare | B5: 1365 | C5: 0% (0) | D5: 0% (0) | E5: 98.61% (1346) | F5: 1.39% (19) | G5: 0% (0) | H5: 0% (0) | I5: 1365 | J5: 0 | K5: 1 | L5: 0 | M5: 6.2833333 | N5: 0 | O5: - | P5: 1 | Q5: 3 | R5: 4
A6: KPT Shalaka Walke | B6: 2655 | C6: 0% (0) | D6: 0% (0) | E6: 96.87% (2572) | F6: 3.13% (83) | G6: 0% (0) | H6: 0% (0) | I6: 2655 | J6: 0 | K6: 1 | L6: 0 | M6: 12.179861 | N6: 0 | O6: - | P6: 0 | Q6: 4 | R6: 4
A7: KPT Ayush Mishra | B7: 2803 | C7: 0% (0) | D7: 0% (0) | E7: 99.46% (2788) | F7: 0.54% (15) | G7: 0% (0) | H7: 0% (0) | I7: 2803 | J7: 0 | K7: 1 | L7: 0 | M7: 9.4041667 | N7: 0 | O7: - | P7: 3 | Q7: 6 | R7: 9
A8: Total | B8: 11597 | C8: 0% (0) | D8: 0% (0) | E8: 98.07% (11373) | F8: 1.93% (224) | G8: 0% (0) | H8: 0% (0) | I8: 11597 | J8: 0 | K8: 1 | L8: 0 | M8: 45.216667 | N8: 0 | O8: - | P8: 10 | Q8: 21 | R8: 31

Sheet T1T2 OSV Defects Total (Tabby_J
A1: Issue Type | B1: Issue key | C1: Issue id | D1: Summary | E1: Assignee | F1: Reporter | G1: Status | H1: Created | I1: Custom field (Defect Rank) | J1: Custom field (Test Process Classification) | K1: Custom field (Management Labels) | L1: Custom field (Management Labels) | M1: Custom field (Management Labels) | N1: Custom field (Management Labels) | O1: Custom field (Management Labels) | P1: Custom field (Management Labels) | Q1: Custom field (Management Labels) | R1: Custom field (Management Labels) | S1: Custom field (Management Labels) | T1: Custom field (Management Labels) | U1: Custom field (Management Labels) | V1: Custom field (Management Labels) | W1: Custom field (Management Labels) | X1: Custom field (Management Labels) | Y1: Custom field (Management Labels) | Z1: Custom field (Management Labels) | AA1: Custom field (Management Labels) | AB1: Custom field (Management Labels) | AC1: Custom field (Management Labels) | AD1: Custom field (Management Labels) | AE1: Custom field (Management Labels) | AF1: Project key | AG1: Project name | AH1: Project type | AI1: Project lead | AJ1: Project description | AK1: Project url
